Workbook

Sheet Data Entry
A1: =TODAY() -> 45810 | E1: PADI Power Partnership Program - I Data Entry
A3: Step 1: | B3: (Enter Store Name & Approximate $ per Category) | E3: Step 2: | F3: (enter certification numbers)
A5: Store Name | E5: Certification Level | G5: Store Certifications
G7: Last Year | H7: Current YTD
E8: Certification Year | F8: 2003 | G8: 2004 | H8: 2005
A9: Percentage of Revenue by Category
C10: enter Store Figures | E10: Open Water | F10: 100 | G10: 215 | H10: 2
A11: =SUM(C11/C18) -> 0.71743929 | B11: Equipment Sales | C11: 325000 | E11: Adventure Diver | F11: 20 | G11: 23 | H11: 0
A12: =SUM(C12/C18) -> 0.18101545 | B12: Travel | C12: 82000 | E12: Advanced | F12: 17 | G12: 35 | H12: 0
A13: =SUM(C13/C18) -> 0.077262693 | B13: Training & Education | C13: 35000 | E13: EFR | F13: 1 | G13: 15 | H13: 3
A14: =SUM(C14/C18) -> 0.014348786 | B14: Service | C14: 6500 | E14: Rescue | F14: 9 | G14: 9 | H14: 0
A15: =SUM(C15/C18) -> 0.0099337748 | B15: Rental | C15: 4500 | E15: Specialties | F15: 28 | G15: 49 | H15: 2
E16: Divemaster | F16: 4 | G16: 5 | H16: 0
E17: Assistant Instructor | F17: 1 | G17: 3 | H17: 1
B18: Total | C18: =SUM(C11:C15) -> 453000 | E18: OWSI | F18: 0 | G18: 2 | H18: 0
E19: PADI Seal Team | F19: 0 | G19: 0 | H19: 0
E20: Bubblemaker | F20: 0 | G20: 15
E21: Total | F21: =SUM(F10:F20) -> 180 | G21: =SUM(G10:G20) -> 371 | H21: =SUM(H10:H20) -> 8
A24: Step 3: | E24: Step 4:
A26: Enter Fixed Expenses on next worksheet | E26: Enter Variable Expenses for each Course Offered
F27: (click appropriate tab)
A30: Certification Numbers based on last full year

Sheet Total Course Profit
A1: =TODAY() -> 45810 | J1: PADI Power Partnership Program - III Total Course Profit
A3: Store Name
B4: ='Data Entry'!B6
C6: Actual Course Cost | F6: Actual Course Price | H6: Profit/Loss Per Student | K6: Profit Margin | M6: Yearly Profit
A7: Open Water | C7: ='Open Water'!K68 -> 194.49561 | F7: ='Open Water'!G70 -> 300 | H7: ='Open Water'!G75 -> 105.50439 | K7: ='Open Water'!G71 -> 0.54245126 | M7: ='Open Water'!G78 -> 22683.444
A8: Adventure Diver | C8: ='Adventure Diver'!L59 -> 7.6592204 | F8: ='Adventure Diver'!G61 -> 0 | H8: ='Adventure Diver'!G66 -> -7.6592204 | K8: ='Adventure Diver'!G62 -> -1 | M8: ='Adventure Diver'!G69 -> -176.16207
A9: Advanced | C9: =Advanced!L59 -> 95.003162 | F9: 0 | H9: =Advanced!G66 -> -95.003162 | K9: =Advanced!G62 -> -1 | M9: =Advanced!G69 -> -3325.1107
A10: EFR | C10: =' EFR'!L59 -> 16.054926 | F10: =' EFR'!G61 -> 0 | H10: =' EFR'!G66 -> -16.054926 | K10: =' EFR'!G62 -> -1 | M10: =' EFR'!G69 -> -240.8239
A11: Rescue | C11: =Rescue!L59 -> 11.257956 | F11: =Rescue!G61 -> 0 | H11: =Rescue!G66 -> -11.257956 | K11: =Rescue!G62 -> -1 | M11: =Rescue!G69 -> -101.3216
A12: Divemaster | C12: =Divemaster!L59 -> 12.643309 | F12: =Divemaster!G61 -> 0 | H12: =Divemaster!G66 -> -12.643309 | K12: =Divemaster!G62 -> -1 | M12: =Divemaster!G69 -> -63.216544
A13: Assistant Instructor | C13: ='Assistant Instructor'!L59 -> 30.085985 | F13: ='Assistant Instructor'!G61 -> 0 | H13: ='Assistant Instructor'!G66 -> -30.085985 | K13: ='Assistant Instructor'!G62 -> -1 | M13: ='Assistant Instructor'!G69 -> -90.257956
A14: OWSI | C14: =OWSI!L59 -> 0.028661759 | F14: =OWSI!G61 -> 0 | H14: =OWSI!G66 -> -0.028661759 | K14: =OWSI!G62 -> -1 | M14: =OWSI!G69 -> -0.028661759
A15: PADI Seal Team | C15: ='PADI Seal Team'!L59 -> 29.166667 | F15: ='PADI Seal Team'!G61 -> 0 | H15: ='PADI Seal Team'!G66 -> -29.166667 | K15: ='PADI Seal Team'!G62 -> -1 | M15: ='PADI Seal Team'!G69 -> 0
A16: Bubblemaker | C16: =Bubblemaker!L59 -> 1.9299264 | F16: =Bubblemaker!G61 -> 0 | H16: =Bubblemaker!G66 -> -1.9299264 | K16: =Bubblemaker!G62 -> -1 | M16: =Bubblemaker!G69 -> -28.948896
B17: Enter Course Name
A18: Specialty 1 | B18: Dry Suit | C18: ='Specialty (1)'!L59 -> 86.596593 | F18: ='Specialty (1)'!G61 -> 130 | H18: ='Specialty (1)'!G66 -> 43.403407 | K18: ='Specialty (1)'!G62 -> 0.50121379 | M18: ='Specialty (1)'!G69 -> 651.0511
A19: Specialty 2 | C19: ='Specialty (2)'!L59 -> 0.028661759 | F19: ='Specialty (2)'!G61 -> 0 | H19: ='Specialty (2)'!G66 -> -0.028661759 | K19: ='Specialty (2)'!G62 -> -1 | M19: ='Specialty (2)'!G69 -> -0.028661759
A20: Specialty 3 | C20: ='Specialty (3)'!L59 -> 0.028661759 | F20: ='Specialty (3)'!G61 -> 0 | H20: ='Specialty (3)'!G66 -> -0.028661759 | K20: ='Specialty (3)'!G62 -> -1 | M20: ='Specialty (3)'!G69 -> -0.028661759
A21: Specialty 4 | C21: ='Specialty (4)'!L59 -> 0.028661759 | F21: ='Specialty (4)'!G61 -> 0 | H21: ='Specialty (4)'!G66 -> -0.028661759 | K21: ='Specialty (4)'!G62 -> -1 | M21: ='Specialty (4)'!G69 -> -0.028661759
A22: Specialty 5 | C22: ='Specialty (5)'!L59 -> 0.028661759 | F22: ='Specialty (5)'!G61 -> 0 | H22: ='Specialty (5)'!G66 -> -0.028661759 | K22: ='Specialty (5)'!G62 -> -1 | M22: ='Specialty (5)'!G69 -> -0.028661759
A23: Specialty 6 | C23: ='Specialty (6)'!L59 -> 0.028661759 | F23: ='Specialty (6)'!G61 -> 0 | H23: ='Specialty (6)'!G66 -> -0.028661759 | K23: ='Specialty (6)'!G62 -> -1 | M23: ='Specialty (6)'!G69 -> -0.028661759
A24: Specialty 7 | C24: ='Specialty (7)'!L59 -> 0.028661759 | F24: ='Specialty (7)'!G61 -> 0 | H24: ='Specialty (7)'!G66 -> -0.028661759 | K24: ='Specialty (7)'!G62 -> -1 | M24: ='Specialty (7)'!G69 -> -0.028661759
A25: Specialty 8 | C25: ='Specialty (8)'!L59 -> 0.028661759 | F25: ='Specialty (8)'!G61 -> 0 | H25: ='Specialty (8)'!G66 -> -0.028661759 | K25: ='Specialty (8)'!G62 -> -1 | M25: ='Specialty (8)'!G69 -> -0.028661759
A26: Specialty 9 | C26: ='Specialty (9)'!L59 -> 0.028661759 | F26: ='Specialty (9)'!G61 -> 0 | H26: ='Specialty (9)'!G66 -> -0.028661759 | K26: ='Specialty (9)'!G62 -> -1 | M26: ='Specialty (9)'!G69 -> -0.028661759
A27: Specialty 10 | C27: ='Specialty (10)'!L59 -> 0.028661759 | F27: ='Specialty (10)'!G61 -> 0 | H27: ='Specialty (10)'!G66 -> -0.028661759 | K27: ='Specialty (10)'!G62 -> -1 | M27: ='Specialty (10)'!G69 -> -0.028661759
A29: Totals | M29: =SUM(M7:M27) -> 19308.366
B30: DO NOT REFLECT EQUIPMENT SALES
B31: ACCOUNTS FOR FIXED & VARIABLE EXPENSES

Sheet  Fixed Expenses
A1: =TODAY() -> 45810 | K1: PADI Power Partnership Program - II Fixed Store Expenses
A3: Store Name: | B3: ='Data Entry'!B6 | K3: Total Students per year: | L3: ='Data Entry'!G21 -> 371
K4: (last Year)
A6: A | B6: Annual fixed expenses
A8: Expenses | D8: Cost | L8: Yearly Cost
A9: Store Liability insurance | D9: 0 | L9: =D9 -> 0
A10: Boat Insurance | D10: 0 | L10: =D10 -> 0
L11: =D11 -> 0
A12: Advertising and Marketing | D12: 0 | E12: (Newsletter, Radio,TV, Yellow Pages, Trade Shows, Print Ads) | L12: =D12 -> 0
A13: Dive Center Fees/Renewals | D13: 0 | L13: =D13 -> 0
A14: Instructor materials | D14: 0 | L14: =D14 -> 0
A15: Other | D15: 0 | L15: =D15 -> 0
A16: Other | D16: 0 | L16: =D16 -> 0
A17: Other | D17: 0 | L17: =D17 -> 0
K19: Sub-total | L19: =SUM(L9:L17) -> 0
A20: B | B20: Fixed expenses lasting several years.
A22: Expenses | D22: Cost | H22: Life | L22: Yearly Cost
A23: Instructional equipment
A24: (computer, LCD projector, TV) | D24: 0 | F24: Cost divided by | H24: 4 | I24: years, total yearly cost | L24: =D24/H24 -> 0
A25: Emergency and Safety equipment | D25: 0 | F25: Cost divided by | H25: 3 | I25: years, total yearly cost | L25: =D25/H25 -> 0
A26: Rental equipment | D26: 0 | F26: Cost divided by | H26: 2 | I26: years, total yearly cost | L26: =D26/H26 -> 0
A27: Compressor Fixture | D27: 0 | F27: Cost divided by | H27: 5 | I27: years, total yearly cost | L27: =D27/H27 -> 0
A28: Office Equipment | D28: 0 | H28: 5 | I28: years, total yearly cost | L28: =SUM(D28/H28) -> 0
A29: Other | D29: 0 | F29: Cost divided by | H29: 1 | I29: years, total yearly cost | L29: =D29/H29 -> 0
A30: Other | D30: 0 | F30: Cost divided by | H30: 1 | I30: years, total yearly cost | L30: =D30/H30 -> 0
A31: Other | D31: 0 | F31: Cost divided by | H31: 1 | I31: years, total yearly cost | L31: =D31/H31 -> 0
K33: Sub-Total | L33: =SUM(L24:L30) -> 0
A34: C | B34: Monthly Fixed Expenses.
A36: Expenses | D36: Cost | L36: Yearly Cost
A37: Rent or Mortage | D37: 3500 | L37: =SUM(D37*12) -> 42000
A38: Employee Payroll | D38: 0 | E38: (Full & Part Time, Divemasters, Boat Personel) | L38: =SUM(D38*12) -> 0
A39: Utilities
B40: Phone | D40: 200 | L40: =SUM(D40*12) -> 2400
B41: Internet | D41: 30 | L41: =SUM(D41*12) -> 360
B42: Electricity | D42: 175 | L42: =SUM(D42*12) -> 2100
B43: Gas | D43: 100 | L43: =SUM(D43*12) -> 1200
A44: Compressor Maintenance | D44: 50 | L44: =SUM(D44*12) -> 600
A45: Pool
B46: Chemicals | D46: 0 | L46: =SUM(D46*12) -> 0
B47: Maintenance | D47: 0 | L47: =SUM(D47*12) -> 0
...

Sheet Open Water
A2: =TODAY() -> 45810 | J2: PADI Power Partnership Program - IV Course Specific Worksheets
A5: Certification Level: | C5: ='Data Entry'!E10 -> Open Water
A8: E | B8: Approximate program size & average
A10: Is this a new program?(Yes or No) | G10: no | J10: Total Students per year: | K10: ='Data Entry'!G21 -> 371
A11: Students per year this level: | G11: ='Data Entry'!G10 -> 215
A12: Average Class size: | G12: 6
A14: F | B14: Determine short-term expenses per student in class
A16: Expenses | G16: Cost
A17: PADI Student Diver Materials | G17: 0 | H17: Cost per student in class | K17: =G17 -> 0
A18: Certificate/Diploma | G18: 1.5 | H18: Cost per student in class | K18: =G18 -> 1.5
A19: Emblem | G19: 3 | H19: Cost per student in class | K19: =G19 -> 3
A20: PIC | G20: 0 | H20: Cost per student in class | K20: =G20 -> 0
A21: Incidentals (Folders, Form, etc) | G21: 5 | H21: Cost per student in class | K21: =G21 -> 5
A22: Boat Fees | G22: 0 | H22: Cost per student in class | K22: =G22 -> 0
A23: Dive Site Entrance Fees | G23: 8 | H23: Cost per student in class | K23: =G23 -> 8
A24: Other | G24: 30 | H24: Cost per student in class | K24: =G24 -> 30
A25: Other | G25: 0 | H25: Cost per student in class | K25: =G25 -> 0
A26: Other | G26: 0 | H26: Cost per student in class | K26: =G26 -> 0
J27: Total | K27: =SUM(K17:K26) -> 47.5
A29: Expenses | G29: Cost
A30: Fee for classroom facilities | G30: 0 | H30: Cost divided by # of students in class | K30: =G30/$G$12 -> 0
B31: Fee for pool facilities (choose either option A,B or C)
E32: # hours
B33: A. Pool Cost per hr. | E33: 15 | G33: 25 | H33: Cost divided by # of students in class | K33: =SUM(E33*G33)/G12 -> 62.5
E34: # sessions
B35: B. Pool Cost per session | E35: 1 | G35: 0 | H35: Cost divided by # of students in class | K35: =SUM((E35*G35)/G12) -> 0
B37: C. Cost per head | G37: 0 | H37: Cost divided by # of students in class | K37: =G37 -> 0
A39: Air fills for pool and Open Water | E39: #fills per diver
E40: 10 | G40: 1.5 | H40: Cost X # of required refills | K40: =SUM(E40*G40) -> 15
A41: Instructor wages per participant | D41: Class&Pool | E41: TD's
B42: (enter pay) | D42: 30 | E42: 30 | G42: =SUM(D42+E42)*G12 -> 360 | H42: Cost divided by # of students in class | K42: =SUM(G42/G12) -> 60
A43: Assistants wages per Course | G43: 20 | H43: Cost divided by # of students in class | K43: =G43/$G$12 -> 3.3333333
A44: Dive Ctr. vehicle; depreciation after one year | G44: 0 | H44: Cost divided by # of students in class | K44: =G44/$G$12 -> 0
A45: Vehicle insurance | G45: 0 | H45: Cost divided by # of students in class | K45: =G45/$G$12 -> 0
A46: Fuel used for course work | G46: 0 | H46: Cost divided by # of students in class | K46: =G46/$G$12 -> 0
A47: Course Specific equipment | E47: Life (years)
E48: 1 | G48: 0 | H48: Cost divided by # of students in class | K48: =SUM(G48/E48)/G12 -> 0
A49: Other | G49: 0 | H49: Cost divided by # of students in class | K49: =G49/$G$12 -> 0
A50: Other | G50: 0 | H50: Cost divided by # of students in class | K50: =G50/$G$12 -> 0
A51: Other | G51: 0 | H51: Cost divided by # of students in class | K51: =G51/$G$12 -> 0
...

Sheet Advanced
A2: Certification Level: | C2: ='Data Entry'!E12 -> Advanced
A5: E | B5: Approximate program size & average
A7: Is this a new program?(Yes or No) | G7: no | K7: Total Students per year: | L7: ='Data Entry'!G21 -> 371
A8: Students per year this level: | G8: ='Data Entry'!G12 -> 35 | H8: (If yes, return to Data Page and enter number)
A9: Average Class size: | G9: 4
A11: F | B11: Determine variable expenses per student in class
A13: Expenses | G13: Cost
A14: PADI Student Diver Materials | G14: 14 | I14: Cost per student in class | L14: =G14 -> 14
A15: Certificate/Diploma | G15: 0 | I15: Cost per student in class | L15: =G15 -> 0
A16: Emblem | G16: 3 | I16: Cost per student in class | L16: =G16 -> 3
A17: PIC | G17: 11 | I17: Cost per student in class | L17: =G17 -> 11
A18: Incidentals (Folders, Form, etc) | G18: 0 | I18: Cost per student in class | L18: =G18 -> 0
A19: Boat Fees | G19: 0 | I19: Cost per student in class | L19: =G19 -> 0
A20: Dive Site Entrance Fees | G20: 20 | I20: Cost per student in class | L20: =G20 -> 20
A21: Other | G21: 0 | I21: Cost per student in class | L21: =G21 -> 0
A22: Other | G22: 0 | I22: Cost per student in class | L22: =G22 -> 0
A23: Other | G23: 0 | I23: Cost per student in class | L23: =G23 -> 0
K24: Total | L24: =SUM(L14:L23) -> 48
A26: Expenses | G26: Cost
A27: Fee for classroom facilities | G27: 0 | I27: Cost divided by # of students in class | L27: =G27/$G$9 -> 0
A28: Fee for pool facilities | G28: 0 | I28: Cost divided by # of students in class | L28: =G28/$G$9 -> 0
A29: Air fills for pool and Open Water | E29: #fills per diver
E30: 9 | G30: 1.5 | I30: Cost X # of required refills | L30: =SUM(E30*G30) -> 13.5
A31: Instructor wages per participant | D31: Class&Pool | E31: TD's
B32: (enter pay) | D32: 0 | E32: 25 | G32: =SUM(D32+E32)*G9 -> 100 | I32: Cost divided by # of students in class | L32: =SUM(G32/G9) -> 25
A33: Assistants wages per Course | G33: 0 | I33: Cost divided by # of students in class | L33: =G33/$G$9 -> 0
A34: Dive Ctr. vehicle; depreciation after one year | G34: 0 | I34: Cost divided by # of students in class | L34: =G34/$G$9 -> 0
A35: Vehicle insurance | G35: 0 | I35: Cost divided by # of students in class | L35: =G35/$G$9 -> 0
A36: Fuel used for course work | G36: 30 | I36: Cost divided by # of students in class | L36: =G36/$G$9 -> 7.5
A37: Course Specific equipment | E37: Life (years)
E38: 1 | G38: 0 | I38: Cost divided by # of students in class | L38: =SUM(G38/E38)/G9 -> 0
A39: Other | G39: 0 | I39: Cost divided by # of students in class | L39: =G39/$G$9 -> 0
A40: Other | G40: 0 | I40: Cost divided by # of students in class | L40: =G40/$G$9 -> 0
A41: Other | G41: 0 | I41: Cost divided by # of students in class | L41: =G41/$G$9 -> 0
I42: Total | L42: =SUM(L27:L41) -> 46
J44: Total Variable Expenses = | L44: =L24+L42 -> 94
A47: G | B47: Desired Profit Margin | G47: 0.25
A49: H | B49: Determine total cost of course per student
K50: Fixed Expenses | L50: =' Fixed Expenses'!L66 -> 10.633512
C52: Total Fixed Expenses = | D52: =SUM(L50*H53) -> 1.0031616 | K52: Cost to certify the Student = | L52: =D54 -> 95.003162
...

Sheet Adventure Diver
A2: Certification Level: | C2: ='Data Entry'!E11 -> Adventure Diver
A5: E | B5: Approximate program size & average
A7: Is this a new program?(Yes or No) | G7: no | K7: Total Students per year: | L7: ='Data Entry'!G21 -> 371
A8: Students per year this level: | G8: ='Data Entry'!G11 -> 23 | H8: (If yes, return to Data Page and enter number)
A9: Average Class size: | G9: 2
A11: F | B11: Determine short-term expenses per student in class
A13: Expenses | G13: Cost
A14: PADI Student Diver Materials | G14: 0 | I14: Cost per student in class | L14: =G14 -> 0
A15: Certificate/Diploma | G15: 0 | I15: Cost per student in class | L15: =G15 -> 0
A16: Emblem | G16: 0 | I16: Cost per student in class | L16: =G16 -> 0
A17: PIC | G17: 0 | I17: Cost per student in class | L17: =G17 -> 0
A18: Incidentals (Folders, Form, etc) | G18: 0 | I18: Cost per student in class | L18: =G18 -> 0
A19: Boat Fees | G19: 0 | I19: Cost per student in class | L19: =G19 -> 0
A20: Dive Site Entrance Fees | G20: 0 | I20: Cost per student in class | L20: =G20 -> 0
A21: Other | G21: 0 | I21: Cost per student in class | L21: =G21 -> 0
A22: Other | G22: 0 | I22: Cost per student in class | L22: =G22 -> 0
A23: Other | G23: 0 | I23: Cost per student in class | L23: =G23 -> 0
K24: Total | L24: =SUM(L14:L23) -> 0
A26: Expenses | G26: Cost
A27: Fee for classroom facilities | G27: 0 | I27: Cost divided by # of students in class | L27: =G27/$G$9 -> 0
A28: Fee for pool facilities | G28: 0 | I28: Cost divided by # of students in class | L28: =G28/$G$9 -> 0
A29: Air fills for pool and Open Water | E29: #fills per diver
E30: 3 | G30: 1.5 | I30: Cost X # of required refills | L30: =SUM(E30*G30) -> 4.5
A31: Instructor wages per participant | D31: Class&Pool | E31: TD's
B32: (enter pay) | D32: 0 | E32: 0 | G32: =SUM(D32+E32)*G9 -> 0 | I32: Cost divided by # of students in class | L32: =SUM(G32/G9) -> 0
A33: Assistants wages per Course | G33: 5 | I33: Cost divided by # of students in class | L33: =G33/$G$9 -> 2.5
A34: Dive Ctr. vehicle; depreciation after one year | G34: 0 | I34: Cost divided by # of students in class | L34: =G34/$G$9 -> 0
A35: Vehicle insurance | G35: 0 | I35: Cost divided by # of students in class | L35: =G35/$G$9 -> 0
A36: Fuel used for course work | G36: 0 | I36: Cost divided by # of students in class | L36: =G36/$G$9 -> 0
A37: Course Specific equipment | E37: Life (years)
E38: 1 | G38: 0 | I38: Cost divided by # of students in class | L38: =SUM(G38/E38)/G9 -> 0
A39: Other | G39: 0 | I39: Cost divided by # of students in class | L39: =G39/$G$9 -> 0
A40: Other | G40: 0 | I40: Cost divided by # of students in class | L40: =G40/$G$9 -> 0
A41: Other | G41: 0 | I41: Cost divided by # of students in class | L41: =G41/$G$9 -> 0
I42: Total | L42: =SUM(L27:L41) -> 7
J44: Total Variable Expenses = | L44: =L24+L42 -> 7
A47: G | B47: Desired Profit Margin | G47: 0.25
A49: H | B49: Determine total cost of course per student
K50: Fixed Expenses | L50: =' Fixed Expenses'!L66 -> 10.633512
C52: Total Fixed Expenses = | D52: =SUM(L50*H53) -> 0.65922045 | K52: Cost to certify the Student = | L52: =D54 -> 7.6592204
...

Sheet  EFR
A2: Certification Level: | C2: Emergency First Response
A5: E | B5: Approximate program size & average
A7: Is this a new program?(Yes or No) | G7: yes | K7: Total Students per year: | L7: ='Data Entry'!G21 -> 371
A8: Students per year this level: | G8: ='Data Entry'!G13 -> 15 | H8: (If yes, return to Data Entry and enter projected student number in certification field)
A9: Average Class size: | G9: 4
A11: F | B11: Determine short-term expenses per student in class
A13: Expenses | G13: Cost
A14: PADI Student Diver Materials | G14: 0 | I14: Cost per student in class | L14: =G14 -> 0
A15: Certificate/Diploma | G15: 0 | I15: Cost per student in class | L15: =G15 -> 0
A16: Emblem | G16: 0 | I16: Cost per student in class | L16: =G16 -> 0
A17: PIC | G17: 0 | I17: Cost per student in class | L17: =G17 -> 0
A18: Incidentals (Folders, Form, etc) | G18: 0 | I18: Cost per student in class | L18: =G18 -> 0
A19: Boat Fees | G19: 0 | I19: Cost per student in class | L19: =G19 -> 0
A20: Dive Site Entrance Fees | G20: 0 | I20: Cost per student in class | L20: =G20 -> 0
A21: Other | G21: 0 | I21: Cost per student in class | L21: =G21 -> 0
A22: Other | G22: 0 | I22: Cost per student in class | L22: =G22 -> 0
A23: Other | G23: 0 | I23: Cost per student in class | L23: =G23 -> 0
K24: Total | L24: =SUM(L14:L23) -> 0
A26: Expenses | G26: Cost
A27: Fee for classroom facilities | G27: 0 | I27: Cost divided by # of students in class | L27: =G27/$G$9 -> 0
A28: Fee for pool facilities | G28: 0 | I28: Cost divided by # of students in class | L28: =G28/$G$9 -> 0
A29: Air fills for pool and Open Water | E29: #fills per diver
E30: 0 | G30: 0 | I30: Cost X # of required refills | L30: =SUM(E30*G30) -> 0
A31: Instructor wages per participant | D31: Class&Pool | E31: TD's
B32: (enter pay) | D32: 0 | E32: 0 | G32: =SUM(D32+E32)*G9 -> 0 | I32: Cost divided by # of students in class | L32: =SUM(G32/G9) -> 0
A33: Assistants wages per Course | G33: 0 | I33: Cost divided by # of students in class | L33: =G33/$G$9 -> 0
A34: Dive Ctr. vehicle; depreciation after one year | G34: 0 | I34: Cost divided by # of students in class | L34: =G34/$G$9 -> 0
A35: Vehicle insurance | G35: 0 | I35: Cost divided by # of students in class | L35: =G35/$G$9 -> 0
A36: Fuel used for course work | G36: 0 | I36: Cost divided by # of students in class | L36: =G36/$G$9 -> 0
A37: Course Specific equipment | E37: Life (years)
A38: Mannequins | E38: 8 | G38: 500 | I38: Cost divided by # of students in class | L38: =SUM(G38/E38)/G9 -> 15.625
A39: Other | G39: 0 | I39: Cost divided by # of students in class | L39: =G39/$G$9 -> 0
A40: Other | G40: 0 | I40: Cost divided by # of students in class | L40: =G40/$G$9 -> 0
A41: Other | G41: 0 | I41: Cost divided by # of students in class | L41: =G41/$G$9 -> 0
I42: Total | L42: =SUM(L27:L41) -> 15.625
J44: Total Variable Expenses = | L44: =L24+L42 -> 15.625
A47: G | B47: Desired Profit Margin | G47: 0.5
A49: H | B49: Determine total cost of course per student
K50: Fixed Expenses | L50: =' Fixed Expenses'!L66 -> 10.633512
C52: Total Fixed Expenses = | D52: =SUM(L50*H53) -> 0.42992638 | K52: Cost to certify the Student = | L52: =D54 -> 16.054926
...

Sheet Rescue
A2: Certification Level: | C2: ='Data Entry'!E14 -> Rescue
A5: E | B5: Approximate program size & average
A7: Is this a new program?(Yes or No) | G7: no | K7: Total Students per year: | L7: ='Data Entry'!G21 -> 371
A8: Students per year this level: | G8: ='Data Entry'!G14 -> 9 | H8: (If yes, return to Data Page and enter number)
A9: Average Class size: | G9: 3
A11: F | B11: Determine short-term expenses per student in class
A13: Expenses | G13: Cost
A14: PADI Student Diver Materials | G14: 0 | I14: Cost per student in class | L14: =G14 -> 0
A15: Certificate/Diploma | G15: 0 | I15: Cost per student in class | L15: =G15 -> 0
A16: Emblem | G16: 0 | I16: Cost per student in class | L16: =G16 -> 0
A17: PIC | G17: 0 | I17: Cost per student in class | L17: =G17 -> 0
A18: Incidentals (Folders, Form, etc) | G18: 0 | I18: Cost per student in class | L18: =G18 -> 0
A19: Boat Fees | G19: 0 | I19: Cost per student in class | L19: =G19 -> 0
A20: Dive Site Entrance Fees | G20: 0 | I20: Cost per student in class | L20: =G20 -> 0
A21: Other | G21: 0 | I21: Cost per student in class | L21: =G21 -> 0
A22: Other | G22: 0 | I22: Cost per student in class | L22: =G22 -> 0
A23: Other | G23: 0 | I23: Cost per student in class | L23: =G23 -> 0
K24: Total | L24: =SUM(L14:L23) -> 0
A26: Expenses | G26: Cost
A27: Fee for classroom facilities | G27: 15 | I27: Cost divided by # of students in class | L27: =G27/$G$9 -> 5
A28: Fee for pool facilities | G28: 0 | I28: Cost divided by # of students in class | L28: =G28/$G$9 -> 0
A29: Air fills for pool and Open Water | E29: #fills per diver
E30: 4 | G30: 1.5 | I30: Cost X # of required refills | L30: =SUM(E30*G30) -> 6
A31: Instructor wages per participant | D31: Class&Pool | E31: TD's
B32: (enter pay) | D32: 0 | E32: 0 | G32: =SUM(D32+E32)*G9 -> 0 | I32: Cost divided by # of students in class | L32: =SUM(G32/G9) -> 0
A33: Assistants wages per Course | G33: 0 | I33: Cost divided by # of students in class | L33: =G33/$G$9 -> 0
A34: Dive Ctr. vehicle; depreciation after one year | G34: 0 | I34: Cost divided by # of students in class | L34: =G34/$G$9 -> 0
A35: Vehicle insurance | G35: 0 | I35: Cost divided by # of students in class | L35: =G35/$G$9 -> 0
A36: Fuel used for course work | G36: 0 | I36: Cost divided by # of students in class | L36: =G36/$G$9 -> 0
A37: Course Specific equipment | E37: Life (years)
E38: 1 | G38: 0 | I38: Cost divided by # of students in class | L38: =SUM(G38/E38)/G9 -> 0
A39: Other | G39: 0 | I39: Cost divided by # of students in class | L39: =G39/$G$9 -> 0
A40: Other | G40: 0 | I40: Cost divided by # of students in class | L40: =G40/$G$9 -> 0
A41: Other | G41: 0 | I41: Cost divided by # of students in class | L41: =G41/$G$9 -> 0
I42: Total | L42: =SUM(L27:L41) -> 11
J44: Total Variable Expenses = | L44: =L24+L42 -> 11
A47: G | B47: Desired Profit Margin | G47: 0.25
A49: H | B49: Determine total cost of course per student
K50: Fixed Expenses | L50: =' Fixed Expenses'!L66 -> 10.633512
C52: Total Fixed Expenses = | D52: =SUM(L50*H53) -> 0.25795583 | K52: Cost to certify the Student = | L52: =D54 -> 11.257956
...

Sheet Divemaster
A2: Certification Level: | C2: ='Data Entry'!E16 -> Divemaster
A5: E | B5: Approximate program size & average
A7: Is this a new program?(Yes or No) | G7: no | K7: Total Students per year: | L7: ='Data Entry'!G21 -> 371
A8: Students per year this level: | G8: ='Data Entry'!G16 -> 5 | H8: (If yes, return to Data Page and enter number)
A9: Average Class size: | G9: 4
A11: F | B11: Determine short-term expenses per student in class
A13: Expenses | G13: Cost
A14: PADI Student Diver Materials | G14: 0 | I14: Cost per student in class | L14: =G14 -> 0
A15: Certificate/Diploma | G15: 0 | I15: Cost per student in class | L15: =G15 -> 0
A16: Emblem | G16: 0 | I16: Cost per student in class | L16: =G16 -> 0
A17: PIC | G17: 0 | I17: Cost per student in class | L17: =G17 -> 0
A18: Incidentals (Folders, Form, etc) | G18: 0 | I18: Cost per student in class | L18: =G18 -> 0
A19: Boat Fees | G19: 0 | I19: Cost per student in class | L19: =G19 -> 0
A20: Dive Site Entrance Fees | G20: 0 | I20: Cost per student in class | L20: =G20 -> 0
A21: Other | G21: 0 | I21: Cost per student in class | L21: =G21 -> 0
A22: Other | G22: 0 | I22: Cost per student in class | L22: =G22 -> 0
A23: Other | G23: 0 | I23: Cost per student in class | L23: =G23 -> 0
K24: Total | L24: =SUM(L14:L23) -> 0
A26: Expenses | G26: Cost
A27: Fee for classroom facilities | G27: 25 | I27: Cost divided by # of students in class | L27: =G27/$G$9 -> 6.25
A28: Fee for pool facilities | G28: 25 | I28: Cost divided by # of students in class | L28: =G28/$G$9 -> 6.25
A29: Air fills for pool and Open Water | E29: #fills per diver
E30: 10 | G30: 0 | I30: Cost X # of required refills | L30: =SUM(E30*G30) -> 0
A31: Instructor wages per participant | D31: Class&Pool | E31: TD's
B32: (enter pay) | D32: 0 | E32: 0 | G32: =SUM(D32+E32)*G9 -> 0 | I32: Cost divided by # of students in class | L32: =SUM(G32/G9) -> 0
A33: Assistants wages per Course | G33: 0 | I33: Cost divided by # of students in class | L33: =G33/$G$9 -> 0
A34: Dive Ctr. vehicle; depreciation after one year | G34: 0 | I34: Cost divided by # of students in class | L34: =G34/$G$9 -> 0
A35: Vehicle insurance | G35: 0 | I35: Cost divided by # of students in class | L35: =G35/$G$9 -> 0
A36: Fuel used for course work | G36: 0 | I36: Cost divided by # of students in class | L36: =G36/$G$9 -> 0
A37: Course Specific equipment | E37: Life (years)
E38: 1 | G38: 0 | I38: Cost divided by # of students in class | L38: =SUM(G38/E38)/G9 -> 0
A39: Other | G39: 0 | I39: Cost divided by # of students in class | L39: =G39/$G$9 -> 0
A40: Other | G40: 0 | I40: Cost divided by # of students in class | L40: =G40/$G$9 -> 0
A41: Other | G41: 0 | I41: Cost divided by # of students in class | L41: =G41/$G$9 -> 0
I42: Total | L42: =SUM(L27:L41) -> 12.5
J44: Total Variable Expenses = | L44: =L24+L42 -> 12.5
A47: G | B47: Desired Profit Margin | G47: 0.25
A49: H | B49: Determine total cost of course per student
K50: Fixed Expenses | L50: =' Fixed Expenses'!L66 -> 10.633512
C52: Total Fixed Expenses = | D52: =SUM(L50*H53) -> 0.14330879 | K52: Cost to certify the Student = | L52: =D54 -> 12.643309
...

Sheet Assistant Instructor
A2: Certification Level: | C2: ='Data Entry'!E17 -> Assistant Instructor
A5: E | B5: Approximate program size & average
A7: Is this a new program?(Yes or No) | G7: yes | K7: Total Students per year: | L7: ='Data Entry'!G21 -> 371
A8: Students per year this level: | G8: ='Data Entry'!G17 -> 3 | H8: (If yes, return to Data Page and enter number)
A9: Average Class size: | G9: 2
A11: F | B11: Determine short-term expenses per student in class
A13: Expenses | G13: Cost
A14: PADI Student Diver Materials | G14: 0 | I14: Cost per student in class | L14: =G14 -> 0
A15: Certificate/Diploma | G15: 0 | I15: Cost per student in class | L15: =G15 -> 0
A16: Emblem | G16: 0 | I16: Cost per student in class | L16: =G16 -> 0
A17: PIC | G17: 0 | I17: Cost per student in class | L17: =G17 -> 0
A18: Incidentals (Folders, Form, etc) | G18: 0 | I18: Cost per student in class | L18: =G18 -> 0
A19: Boat Fees | G19: 0 | I19: Cost per student in class | L19: =G19 -> 0
A20: Dive Site Entrance Fees | G20: 0 | I20: Cost per student in class | L20: =G20 -> 0
A21: Other | G21: 0 | I21: Cost per student in class | L21: =G21 -> 0
A22: Other | G22: 0 | I22: Cost per student in class | L22: =G22 -> 0
A23: Other | G23: 0 | I23: Cost per student in class | L23: =G23 -> 0
K24: Total | L24: =SUM(L14:L23) -> 0
A26: Expenses | G26: Cost
A27: Fee for classroom facilities | G27: 25 | I27: Cost divided by # of students in class | L27: =G27/$G$9 -> 12.5
A28: Fee for pool facilities | G28: 35 | I28: Cost divided by # of students in class | L28: =G28/$G$9 -> 17.5
A29: Air fills for pool and Open Water | E29: #fills per diver
E30: 0 | G30: 0 | I30: Cost X # of required refills | L30: =SUM(E30*G30) -> 0
A31: Instructor wages per participant | D31: Class&Pool | E31: TD's
B32: (enter pay) | D32: 0 | E32: 0 | G32: =SUM(D32+E32)*G9 -> 0 | I32: Cost divided by # of students in class | L32: =SUM(G32/G9) -> 0
A33: Assistants wages per Course | G33: 0 | I33: Cost divided by # of students in class | L33: =G33/$G$9 -> 0
A34: Dive Ctr. vehicle; depreciation after one year | G34: 0 | I34: Cost divided by # of students in class | L34: =G34/$G$9 -> 0
A35: Vehicle insurance | G35: 0 | I35: Cost divided by # of students in class | L35: =G35/$G$9 -> 0
A36: Fuel used for course work | G36: 0 | I36: Cost divided by # of students in class | L36: =G36/$G$9 -> 0
A37: Course Specific equipment | E37: Life (years)
E38: 1 | G38: 0 | I38: Cost divided by # of students in class | L38: =SUM(G38/E38)/G9 -> 0
A39: Other | G39: 0 | I39: Cost divided by # of students in class | L39: =G39/$G$9 -> 0
A40: Other | G40: 0 | I40: Cost divided by # of students in class | L40: =G40/$G$9 -> 0
A41: Other | G41: 0 | I41: Cost divided by # of students in class | L41: =G41/$G$9 -> 0
I42: Total | L42: =SUM(L27:L41) -> 30
J44: Total Variable Expenses = | L44: =L24+L42 -> 30
A47: G | B47: Desired Profit Margin | G47: 0.25
A49: H | B49: Determine total cost of course per student
K50: Fixed Expenses | L50: =' Fixed Expenses'!L66 -> 10.633512
C52: Total Fixed Expenses = | D52: =SUM(L50*H53) -> 0.085985276 | K52: Cost to certify the Student = | L52: =D54 -> 30.085985
...

Sheet OWSI
A2: Certification Level: | C2: ='Data Entry'!E18 -> OWSI
A5: E | B5: Approximate program size & average
A7: Is this a new program?(Yes or No) | G7: no | K7: Total Students per year: | L7: ='Data Entry'!G21 -> 371
A8: Students per year this level: | G8: 1 | H8: (If yes, return to Data Page and enter number)
A9: Average Class size: | G9: 1
A11: F | B11: Determine short-term expenses per student in class
A13: Expenses | G13: Cost
A14: PADI Student Diver Materials | G14: 0 | I14: Cost per student in class | L14: =G14 -> 0
A15: Certificate/Diploma | G15: 0 | I15: Cost per student in class | L15: =G15 -> 0
A16: Emblem | G16: 0 | I16: Cost per student in class | L16: =G16 -> 0
A17: PIC | G17: 0 | I17: Cost per student in class | L17: =G17 -> 0
A18: Incidentals (Folders, Form, etc) | G18: 0 | I18: Cost per student in class | L18: =G18 -> 0
A19: Boat Fees | G19: 0 | I19: Cost per student in class | L19: =G19 -> 0
A20: Dive Site Entrance Fees | G20: 0 | I20: Cost per student in class | L20: =G20 -> 0
A21: Other | G21: 0 | I21: Cost per student in class | L21: =G21 -> 0
A22: Other | G22: 0 | I22: Cost per student in class | L22: =G22 -> 0
A23: Other | G23: 0 | I23: Cost per student in class | L23: =G23 -> 0
K24: Total | L24: =SUM(L14:L23) -> 0
A26: Expenses | G26: Cost
A27: Fee for classroom facilities | G27: 0 | I27: Cost divided by # of students in class | L27: =G27/$G$9 -> 0
A28: Fee for pool facilities | G28: 0 | I28: Cost divided by # of students in class | L28: =G28/$G$9 -> 0
A29: Air fills for pool and Open Water | E29: #fills per diver
E30: 0 | G30: 0 | I30: Cost X # of required refills | L30: =SUM(E30*G30) -> 0
A31: Instructor wages per participants | D31: Class&Pool | E31: TD's | G31: 0
B32: (enter pay) | D32: 0 | E32: 0 | G32: =SUM(D32+E32)*G9 -> 0 | I32: Cost divided by # of students in class | L32: =SUM(G32/G9) -> 0
A33: Assistants wages per Course | G33: 0 | I33: Cost divided by # of students in class | L33: =G33/$G$9 -> 0
A34: Dive Ctr. vehicle; depreciation after one year | G34: 0 | I34: Cost divided by # of students in class | L34: =G34/$G$9 -> 0
A35: Vehicle insurance | G35: 0 | I35: Cost divided by # of students in class | L35: =G35/$G$9 -> 0
A36: Fuel used for course work | G36: 0 | I36: Cost divided by # of students in class | L36: =G36/$G$9 -> 0
A37: Course Specific equipment | E37: Life (years)
E38: 1 | G38: 0 | I38: Cost divided by # of students in class | L38: =SUM(G38/E38)/G9 -> 0
A39: Other | G39: 0 | I39: Cost divided by # of students in class | L39: =G39/$G$9 -> 0
A40: Other | G40: 0 | I40: Cost divided by # of students in class | L40: =G40/$G$9 -> 0
A41: Other | G41: 0 | I41: Cost divided by # of students in class | L41: =G41/$G$9 -> 0
I42: Total | L42: =SUM(L27:L41) -> 0
J44: Total Variable Expenses = | L44: =L24+L42 -> 0
A47: G | B47: Desired Profit Margin | G47: 0.25
A49: H | B49: Determine total cost of course per student
K50: Fixed Expenses | L50: =' Fixed Expenses'!L66 -> 10.633512
C52: Total Fixed Expenses = | D52: =SUM(L50*H53) -> 0.028661759 | K52: Cost to certify the Student = | L52: =D54 -> 0.028661759
...

Sheet PADI Seal Team
A2: Certification Level: | C2: PADI Seal Team
A5: E | B5: Approximate program size & average
A7: Is this a new program?(Yes or No) | G7: no | K7: Total Students per year: | L7: ='Data Entry'!G21 -> 371
A8: Students per year this level: | G8: ='Data Entry'!G19 -> 0 | H8: (If yes, return to Data Page and enter number)
A9: Average Class size: | G9: 10
A11: F | B11: Determine short-term expenses per student in class
A13: Expenses | G13: Cost
A14: PADI Student Diver Materials | G14: 0 | I14: Cost per student in class | L14: =G14 -> 0
A15: Certificate/Diploma | G15: 0 | I15: Cost per student in class | L15: =G15 -> 0
A16: Emblem | G16: 0 | I16: Cost per student in class | L16: =G16 -> 0
A17: PIC | G17: 0 | I17: Cost per student in class | L17: =G17 -> 0
A18: Incidentals (Folders, Form, etc) | G18: 0 | I18: Cost per student in class | L18: =G18 -> 0
A19: Boat Fees | G19: 0 | I19: Cost per student in class | L19: =G19 -> 0
A20: Dive Site Entrance Fees | G20: 0 | I20: Cost per student in class | L20: =G20 -> 0
A21: Other | G21: 0 | I21: Cost per student in class | L21: =G21 -> 0
A22: Other | G22: 0 | I22: Cost per student in class | L22: =G22 -> 0
A23: Other | G23: 0 | I23: Cost per student in class | L23: =G23 -> 0
K24: Total | L24: =SUM(L14:L23) -> 0
A26: Expenses | G26: Cost
A27: Fee for classroom facilities | G27: 0 | I27: Cost divided by # of students in class | L27: =G27/$G$9 -> 0
A28: Fee for pool facilities | G28: 0 | I28: Cost divided by # of students in class | L28: =G28/$G$9 -> 0
A29: Air fills for pool and Open Water | E29: #fills per diver
E30: 15 | G30: 1.5 | I30: Cost X # of required refills | L30: =SUM(E30*G30) -> 22.5
A31: Instructor wages per participant | D31: Class&Pool | E31: TD's
B32: (enter pay) | D32: 0 | E32: 0 | G32: =SUM(D32+E32)*G9 -> 0 | I32: Cost divided by # of students in class | L32: =SUM(G32/G9) -> 0
A33: Assistants wages per Course | G33: 0 | I33: Cost divided by # of students in class | L33: =G33/$G$9 -> 0
A34: Dive Ctr. vehicle; depreciation after one year | G34: 0 | I34: Cost divided by # of students in class | L34: =G34/$G$9 -> 0
A35: Vehicle insurance | G35: 0 | I35: Cost divided by # of students in class | L35: =G35/$G$9 -> 0
A36: Fuel used for course work | G36: 0 | I36: Cost divided by # of students in class | L36: =G36/$G$9 -> 0
A37: Course Specific equipment | E37: Life (years)
E38: 3 | G38: 200 | I38: Cost divided by # of students in class | L38: =SUM(G38/E38)/G9 -> 6.6666667
A39: Other | G39: 0 | I39: Cost divided by # of students in class | L39: =G39/$G$9 -> 0
A40: Other | G40: 0 | I40: Cost divided by # of students in class | L40: =G40/$G$9 -> 0
A41: Other | G41: 0 | I41: Cost divided by # of students in class | L41: =G41/$G$9 -> 0
I42: Total | L42: =SUM(L27:L41) -> 29.166667
J44: Total Variable Expenses = | L44: =L24+L42 -> 29.166667
A47: G | B47: Desired Profit Margin | G47: 0.25
A49: H | B49: Determine total cost of course per student
K50: Fixed Expenses | L50: =' Fixed Expenses'!L66 -> 10.633512
C52: Total Fixed Expenses = | D52: =SUM(L50*H53) -> 0 | K52: Cost to certify the Student = | L52: =D54 -> 29.166667
...

Sheet Bubblemaker
A2: Certification Level: | C2: ='Data Entry'!E20 -> Bubblemaker
A5: E | B5: Approximate program size & average
A7: Is this a new program?(Yes or No) | G7: no | K7: Total Students per year: | L7: ='Data Entry'!G21 -> 371
A8: Students per year this level: | G8: ='Data Entry'!G20 -> 15 | H8: (If yes, return to Data Page and enter number)
A9: Average Class size: | G9: 8
A11: F | B11: Determine short-term expenses per student in class
A13: Expenses | G13: Cost
A14: PADI Student Diver Materials | G14: 0 | I14: Cost per student in class | L14: =G14 -> 0
A15: Certificate/Diploma | G15: 0 | I15: Cost per student in class | L15: =G15 -> 0
A16: Emblem | G16: 0 | I16: Cost per student in class | L16: =G16 -> 0
A17: PIC | G17: 0 | I17: Cost per student in class | L17: =G17 -> 0
A18: Incidentals (Folders, Form, etc) | G18: 0 | I18: Cost per student in class | L18: =G18 -> 0
A19: Boat Fees | G19: 0 | I19: Cost per student in class | L19: =G19 -> 0
A20: Dive Site Entrance Fees | G20: 0 | I20: Cost per student in class | L20: =G20 -> 0
A21: Other | G21: 0 | I21: Cost per student in class | L21: =G21 -> 0
A22: Other | G22: 0 | I22: Cost per student in class | L22: =G22 -> 0
A23: Other | G23: 0 | I23: Cost per student in class | L23: =G23 -> 0
K24: Total | L24: =SUM(L14:L23) -> 0
A26: Expenses | G26: Cost
A27: Fee for classroom facilities | G27: 0 | I27: Cost divided by # of students in class | L27: =G27/$G$9 -> 0
A28: Fee for pool facilities | G28: 0 | I28: Cost divided by # of students in class | L28: =G28/$G$9 -> 0
A29: Air fills for pool and Open Water | E29: #fills per diver
E30: 1 | G30: 1.5 | I30: Cost X # of required refills | L30: =SUM(E30*G30) -> 1.5
A31: Instructor wages per participant | D31: Class&Pool | E31: TD's
B32: (enter pay) | D32: 0 | E32: 0 | G32: =SUM(D32+E32)*G9 -> 0 | I32: Cost divided by # of students in class | L32: =SUM(G32/G9) -> 0
A33: Assistants wages per Course | G33: 0 | I33: Cost divided by # of students in class | L33: =G33/$G$9 -> 0
A34: Dive Ctr. vehicle; depreciation after one year | G34: 0 | I34: Cost divided by # of students in class | L34: =G34/$G$9 -> 0
A35: Vehicle insurance | G35: 0 | I35: Cost divided by # of students in class | L35: =G35/$G$9 -> 0
A36: Fuel used for course work | G36: 0 | I36: Cost divided by # of students in class | L36: =G36/$G$9 -> 0
A37: Course Specific equipment | E37: Life (years)
E38: 1 | G38: 0 | I38: Cost divided by # of students in class | L38: =SUM(G38/E38)/G9 -> 0
A39: Birthday Cake | G39: 0 | I39: Cost divided by # of students in class | L39: =G39/$G$9 -> 0
A40: Soda Pop | G40: 0 | I40: Cost divided by # of students in class | L40: =G40/$G$9 -> 0
A41: Party Items | G41: 0 | I41: Cost divided by # of students in class | L41: =G41/$G$9 -> 0
I42: Total | L42: =SUM(L27:L41) -> 1.5
J44: Total Variable Expenses = | L44: =L24+L42 -> 1.5
A47: G | B47: Desired Profit Margin | G47: 0.35
A49: H | B49: Determine total cost of course per student
K50: Fixed Expenses | L50: =' Fixed Expenses'!L66 -> 10.633512
C52: Total Fixed Expenses = | D52: =SUM(L50*H53) -> 0.42992638 | K52: Cost to certify the Student = | L52: =D54 -> 1.9299264
...

Sheet Specialty (1)
A2: Certification Level: | C2: ='Total Course Profit'!B18 -> Dry Suit
A5: E | B5: Approximate program size & average
A7: Is this a new program?(Yes or No) | G7: yes | K7: Total Students per year: | L7: ='Data Entry'!G21 -> 371
A8: Students per year this level: | G8: 15
A9: Average Class size: | G9: 3
A11: F | B11: Determine short-term expenses per student in class
A13: Expenses | G13: Cost
A14: PADI Student Diver Materials | G14: 15 | I14: Cost per student in class | L14: =G14 -> 15
A15: Certificate/Diploma | G15: 0 | I15: Cost per student in class | L15: =G15 -> 0
A16: Emblem | G16: 0 | I16: Cost per student in class | L16: =G16 -> 0
A17: PIC | G17: 10 | I17: Cost per student in class | L17: =G17 -> 10
A18: Incidentals (Folders, Form, etc) | G18: 0 | I18: Cost per student in class | L18: =G18 -> 0
A19: Boat Fees | G19: 0 | I19: Cost per student in class | L19: =G19 -> 0
A20: Dive Site Entrance Fees | G20: 0 | I20: Cost per student in class | L20: =G20 -> 0
A21: Other | G21: 0 | I21: Cost per student in class | L21: =G21 -> 0
A22: Other | G22: 0 | I22: Cost per student in class | L22: =G22 -> 0
A23: Other | G23: 0 | I23: Cost per student in class | L23: =G23 -> 0
K24: Total | L24: =SUM(L14:L23) -> 25
A26: Expenses | G26: Cost
A27: Fee for classroom facilities | G27: 0 | I27: Cost divided by # of students in class | L27: =G27/$G$9 -> 0
A28: Fee for pool facilities | G28: 0 | I28: Cost divided by # of students in class | L28: =G28/$G$9 -> 0
A29: Air fills for pool and Open Water | E29: #fills per diver
E30: 2 | G30: 1 | I30: Cost X # of required refills | L30: =SUM(E30*G30) -> 2
A31: Instructor wages per participant | D31: Class&Pool | E31: TD's
B32: (enter pay) | D32: 0 | E32: 30 | G32: =SUM(D32+E32)*G9 -> 90 | I32: Cost divided by # of students in class | L32: =SUM(G32/G9) -> 30
A33: Assistants wages per Course | G33: 0 | I33: Cost divided by # of students in class | L33: =G33/$G$9 -> 0
A34: Dive Ctr. vehicle; depreciation after one year | G34: 0 | I34: Cost divided by # of students in class | L34: =G34/$G$9 -> 0
A35: Vehicle insurance | G35: 0 | I35: Cost divided by # of students in class | L35: =G35/$G$9 -> 0
A36: Fuel used for course work | G36: 25 | I36: Cost divided by # of students in class | L36: =G36/$G$9 -> 8.3333333
A37: Course Specific equipment | E37: Life (years)
E38: 4 | G38: 250 | I38: Cost divided by # of students in class | L38: =SUM(G38/E38)/G9 -> 20.833333
A39: Other | G39: 0 | I39: Cost divided by # of students in class | L39: =G39/$G$9 -> 0
A40: Other | G40: 0 | I40: Cost divided by # of students in class | L40: =G40/$G$9 -> 0
A41: Other | G41: 0 | I41: Cost divided by # of students in class | L41: =G41/$G$9 -> 0
I42: Total | L42: =SUM(L27:L41) -> 61.166667
J44: Total Variable Expenses = | L44: =L24+L42 -> 86.166667
A47: G | B47: Desired Profit Margin | G47: 0.5
A49: H | B49: Determine total cost of course per student
K50: Fixed Expenses | L50: =' Fixed Expenses'!L66 -> 10.633512
C52: Total Fixed Expenses = | D52: =SUM(L50*H53) -> 0.42992638 | K52: Cost to certify the Student = | L52: =D54 -> 86.596593
...

Sheet Specialty (2)
A2: Certification Level: | C2: ='Total Course Profit'!B19
A5: E | B5: Approximate program size & average
A7: Is this a new program?(Yes or No) | G7: no | K7: Total Students per year: | L7: ='Data Entry'!G21 -> 371
A8: Students per year this level: | G8: 1
A9: Average Class size: | G9: 1
A11: F | B11: Determine short-term expenses per student in class
A13: Expenses | G13: Cost
A14: PADI Student Diver Materials | G14: 0 | I14: Cost per student in class | L14: =G14 -> 0
A15: Certificate/Diploma | G15: 0 | I15: Cost per student in class | L15: =G15 -> 0
A16: Emblem | G16: 0 | I16: Cost per student in class | L16: =G16 -> 0
A17: PIC | G17: 0 | I17: Cost per student in class | L17: =G17 -> 0
A18: Incidentals (Folders, Form, etc) | G18: 0 | I18: Cost per student in class | L18: =G18 -> 0
A19: Boat Fees | G19: 0 | I19: Cost per student in class | L19: =G19 -> 0
A20: Dive Site Entrance Fees | G20: 0 | I20: Cost per student in class | L20: =G20 -> 0
A21: Other | G21: 0 | I21: Cost per student in class | L21: =G21 -> 0
A22: Other | G22: 0 | I22: Cost per student in class | L22: =G22 -> 0
A23: Other | G23: 0 | I23: Cost per student in class | L23: =G23 -> 0
K24: Total | L24: =SUM(L14:L23) -> 0
A26: Expenses | G26: Cost
A27: Fee for classroom facilities | G27: 0 | I27: Cost divided by # of students in class | L27: =G27/$G$9 -> 0
A28: Fee for pool facilities | G28: 0 | I28: Cost divided by # of students in class | L28: =G28/$G$9 -> 0
A29: Air fills for pool and Open Water | E29: #fills per diver
E30: 0 | G30: 0 | I30: Cost X # of required refills | L30: =SUM(E30*G30) -> 0
A31: Instructor wages per participant | D31: Class&Pool | E31: TD's
B32: (enter pay) | D32: 0 | E32: 0 | G32: =SUM(D32+E32)*G9 -> 0 | I32: Cost divided by # of students in class | L32: =SUM(G32/G9) -> 0
A33: Assistants wages per Course | G33: 0 | I33: Cost divided by # of students in class | L33: =G33/$G$9 -> 0
A34: Dive Ctr. vehicle; depreciation after one year | G34: 0 | I34: Cost divided by # of students in class | L34: =G34/$G$9 -> 0
A35: Vehicle insurance | G35: 0 | I35: Cost divided by # of students in class | L35: =G35/$G$9 -> 0
A36: Fuel used for course work | G36: 0 | I36: Cost divided by # of students in class | L36: =G36/$G$9 -> 0
A37: Course Specific equipment | E37: Life (years)
E38: 1 | G38: 0 | I38: Cost divided by # of students in class | L38: =SUM(G38/E38)/G9 -> 0
A39: Other | G39: 0 | I39: Cost divided by # of students in class | L39: =G39/$G$9 -> 0
A40: Other | G40: 0 | I40: Cost divided by # of students in class | L40: =G40/$G$9 -> 0
A41: Other | G41: 0 | I41: Cost divided by # of students in class | L41: =G41/$G$9 -> 0
I42: Total | L42: =SUM(L27:L41) -> 0
J44: Total Variable Expenses= | L44: =L24+L42 -> 0
A47: G | B47: Desired Profit Margin | G47: 0.25
A49: H | B49: Determine total cost of course per student
K50: Fixed Expenses | L50: =' Fixed Expenses'!L66 -> 10.633512
C52: Total Fixed Expenses = | D52: =SUM(L50*H53) -> 0.028661759 | K52: Cost to certify the Student = | L52: =D54 -> 0.028661759
...

Sheet Specialty (3)
A2: Certification Level: | C2: ='Total Course Profit'!B20
A5: E | B5: Approximate program size & average
A7: Is this a new program?(Yes or No) | G7: no | K7: Total Students per year: | L7: ='Data Entry'!G21 -> 371
A8: Students per year this level: | G8: 1
A9: Average Class size: | G9: 1
A11: F | B11: Determine short-term expenses per student in class
A13: Expenses | G13: Cost
A14: PADI Student Diver Materials | G14: 0 | I14: Cost per student in class | L14: =G14 -> 0
A15: Certificate/Diploma | G15: 0 | I15: Cost per student in class | L15: =G15 -> 0
A16: Emblem | G16: 0 | I16: Cost per student in class | L16: =G16 -> 0
A17: PIC | G17: 0 | I17: Cost per student in class | L17: =G17 -> 0
A18: Incidentals (Folders, Form, etc) | G18: 0 | I18: Cost per student in class | L18: =G18 -> 0
A19: Boat Fees | G19: 0 | I19: Cost per student in class | L19: =G19 -> 0
A20: Dive Site Entrance Fees | G20: 0 | I20: Cost per student in class | L20: =G20 -> 0
A21: Other | G21: 0 | I21: Cost per student in class | L21: =G21 -> 0
A22: Other | G22: 0 | I22: Cost per student in class | L22: =G22 -> 0
A23: Other | G23: 0 | I23: Cost per student in class | L23: =G23 -> 0
K24: Total | L24: =SUM(L14:L23) -> 0
A26: Expenses | G26: Cost
A27: Fee for classroom facilities | G27: 0 | I27: Cost divided by # of students in class | L27: =G27/$G$9 -> 0
A28: Fee for pool facilities | G28: 0 | I28: Cost divided by # of students in class | L28: =G28/$G$9 -> 0
A29: Air fills for pool and Open Water | E29: #fills per diver
E30: 0 | G30: 0 | I30: Cost X # of required refills | L30: =SUM(E30*G30) -> 0
A31: Instructor wages per participant | D31: Class&Pool | E31: TD's
B32: (enter pay) | D32: 0 | E32: 0 | G32: =SUM(D32+E32)*G9 -> 0 | I32: Cost divided by # of students in class | L32: =SUM(G32/G9) -> 0
A33: Assistants wages per Course | G33: 0 | I33: Cost divided by # of students in class | L33: =G33/$G$9 -> 0
A34: Dive Ctr. vehicle; depreciation after one year | G34: 0 | I34: Cost divided by # of students in class | L34: =G34/$G$9 -> 0
A35: Vehicle insurance | G35: 0 | I35: Cost divided by # of students in class | L35: =G35/$G$9 -> 0
A36: Fuel used for course work | G36: 0 | I36: Cost divided by # of students in class | L36: =G36/$G$9 -> 0
A37: Course Specific equipment | E37: Life (years)
E38: 1 | G38: 0 | I38: Cost divided by # of students in class | L38: =SUM(G38/E38)/G9 -> 0
A39: Other | G39: 0 | I39: Cost divided by # of students in class | L39: =G39/$G$9 -> 0
A40: Other | G40: 0 | I40: Cost divided by # of students in class | L40: =G40/$G$9 -> 0
A41: Other | G41: 0 | I41: Cost divided by # of students in class | L41: =G41/$G$9 -> 0
I42: Total | L42: =SUM(L27:L41) -> 0
J44: Total Variable Expenses= | L44: =L24+L42 -> 0
A47: G | B47: Desired Profit Margin | G47: 0.25
A49: H | B49: Determine total cost of course per student
K50: Fixed Expenses | L50: =' Fixed Expenses'!L66 -> 10.633512
C52: Total Fixed Expenses = | D52: =SUM(L50*H53) -> 0.028661759 | K52: Cost to certify the Student = | L52: =D54 -> 0.028661759
...

Sheet Specialty (4)
A2: Certification Level: | C2: ='Total Course Profit'!B21
A5: E | B5: Approximate program size & average
A7: Is this a new program?(Yes or No) | G7: no | K7: Total Students per year: | L7: ='Data Entry'!G21 -> 371
A8: Students per year this level: | G8: 1
A9: Average Class size: | G9: 1
A11: F | B11: Determine short-term expenses per student in class
A13: Expenses | G13: Cost
A14: PADI Student Diver Materials | G14: 0 | I14: Cost per student in class | L14: =G14 -> 0
A15: Certificate/Diploma | G15: 0 | I15: Cost per student in class | L15: =G15 -> 0
A16: Emblem | G16: 0 | I16: Cost per student in class | L16: =G16 -> 0
A17: PIC | G17: 0 | I17: Cost per student in class | L17: =G17 -> 0
A18: Incidentals (Folders, Form, etc) | G18: 0 | I18: Cost per student in class | L18: =G18 -> 0
A19: Boat Fees | G19: 0 | I19: Cost per student in class | L19: =G19 -> 0
A20: Dive Site Entrance Fees | G20: 0 | I20: Cost per student in class | L20: =G20 -> 0
A21: Other | G21: 0 | I21: Cost per student in class | L21: =G21 -> 0
A22: Other | G22: 0 | I22: Cost per student in class | L22: =G22 -> 0
A23: Other | G23: 0 | I23: Cost per student in class | L23: =G23 -> 0
K24: Total | L24: =SUM(L14:L23) -> 0
A26: Expenses | G26: Cost
A27: Fee for classroom facilities | G27: 0 | I27: Cost divided by # of students in class | L27: =G27/$G$9 -> 0
A28: Fee for pool facilities | G28: 0 | I28: Cost divided by # of students in class | L28: =G28/$G$9 -> 0
A29: Air fills for pool and Open Water | E29: #fills per diver
E30: 0 | G30: 0 | I30: Cost X # of required refills | L30: =SUM(E30*G30) -> 0
A31: Instructor wages per participant | D31: Class&Pool | E31: TD's
B32: (enter pay) | D32: 0 | E32: 0 | G32: =SUM(D32+E32)*G9 -> 0 | I32: Cost divided by # of students in class | L32: =SUM(G32/G9) -> 0
A33: Assistants wages per Course | G33: 0 | I33: Cost divided by # of students in class | L33: =G33/$G$9 -> 0
A34: Dive Ctr. vehicle; depreciation after one year | G34: 0 | I34: Cost divided by # of students in class | L34: =G34/$G$9 -> 0
A35: Vehicle insurance | G35: 0 | I35: Cost divided by # of students in class | L35: =G35/$G$9 -> 0
A36: Fuel used for course work | G36: 0 | I36: Cost divided by # of students in class | L36: =G36/$G$9 -> 0
A37: Course Specific equipment | E37: Life (years)
E38: 1 | G38: 0 | I38: Cost divided by # of students in class | L38: =SUM(G38/E38)/G9 -> 0
A39: Other | G39: 0 | I39: Cost divided by # of students in class | L39: =G39/$G$9 -> 0
A40: Other | G40: 0 | I40: Cost divided by # of students in class | L40: =G40/$G$9 -> 0
A41: Other | G41: 0 | I41: Cost divided by # of students in class | L41: =G41/$G$9 -> 0
I42: Total | L42: =SUM(L27:L41) -> 0
J44: Total Variable Expenses= | L44: =L24+L42 -> 0
A47: G | B47: Desired Profit Margin | G47: 0.25
A49: H | B49: Determine total cost of course per student
K50: Fixed Expenses | L50: =' Fixed Expenses'!L66 -> 10.633512
C52: Total Fixed Expenses = | D52: =SUM(L50*H53) -> 0.028661759 | K52: Cost to certify the Student = | L52: =D54 -> 0.028661759
...

Sheet Specialty (5)
A2: Certification Level: | C2: ='Total Course Profit'!B22
A5: E | B5: Approximate program size & average
A7: Is this a new program?(Yes or No) | G7: no | K7: Total Students per year: | L7: ='Data Entry'!G21 -> 371
A8: Students per year this level: | G8: 1
A9: Average Class size: | G9: 1
A11: F | B11: Determine short-term expenses per student in class
A13: Expenses | G13: Cost
A14: PADI Student Diver Materials | G14: 0 | I14: Cost per student in class | L14: =G14 -> 0
A15: Certificate/Diploma | G15: 0 | I15: Cost per student in class | L15: =G15 -> 0
A16: Emblem | G16: 0 | I16: Cost per student in class | L16: =G16 -> 0
A17: PIC | G17: 0 | I17: Cost per student in class | L17: =G17 -> 0
A18: Incidentals (Folders, Form, etc) | G18: 0 | I18: Cost per student in class | L18: =G18 -> 0
A19: Boat Fees | G19: 0 | I19: Cost per student in class | L19: =G19 -> 0
A20: Dive Site Entrance Fees | G20: 0 | I20: Cost per student in class | L20: =G20 -> 0
A21: Other | G21: 0 | I21: Cost per student in class | L21: =G21 -> 0
A22: Other | G22: 0 | I22: Cost per student in class | L22: =G22 -> 0
A23: Other | G23: 0 | I23: Cost per student in class | L23: =G23 -> 0
K24: Total | L24: =SUM(L14:L23) -> 0
A26: Expenses | G26: Cost
A27: Fee for classroom facilities | G27: 0 | I27: Cost divided by # of students in class | L27: =G27/$G$9 -> 0
A28: Fee for pool facilities | G28: 0 | I28: Cost divided by # of students in class | L28: =G28/$G$9 -> 0
A29: Air fills for pool and Open Water | E29: #fills per diver
E30: 0 | G30: 0 | I30: Cost X # of required refills | L30: =SUM(E30*G30) -> 0
A31: Instructor wages per participant | D31: Class&Pool | E31: TD's
B32: (enter pay) | D32: 0 | E32: 0 | G32: =SUM(D32+E32)*G9 -> 0 | I32: Cost divided by # of students in class | L32: =SUM(G32/G9) -> 0
A33: Assistants wages per Course | G33: 0 | I33: Cost divided by # of students in class | L33: =G33/$G$9 -> 0
A34: Dive Ctr. vehicle; depreciation after one year | G34: 0 | I34: Cost divided by # of students in class | L34: =G34/$G$9 -> 0
A35: Vehicle insurance | G35: 0 | I35: Cost divided by # of students in class | L35: =G35/$G$9 -> 0
A36: Fuel used for course work | G36: 0 | I36: Cost divided by # of students in class | L36: =G36/$G$9 -> 0
A37: Course Specific equipment | E37: Life (years)
E38: 1 | G38: 0 | I38: Cost divided by # of students in class | L38: =SUM(G38/E38)/G9 -> 0
A39: Other | G39: 0 | I39: Cost divided by # of students in class | L39: =G39/$G$9 -> 0
A40: Other | G40: 0 | I40: Cost divided by # of students in class | L40: =G40/$G$9 -> 0
A41: Other | G41: 0 | I41: Cost divided by # of students in class | L41: =G41/$G$9 -> 0
I42: Total | L42: =SUM(L27:L41) -> 0
J44: Total Variable Expenses= | L44: =L24+L42 -> 0
A47: G | B47: Desired Profit Margin | G47: 0.25
A49: H | B49: Determine total cost of course per student
K50: Fixed Expenses | L50: =' Fixed Expenses'!L66 -> 10.633512
C52: Total Fixed Expenses = | D52: =SUM(L50*H53) -> 0.028661759 | K52: Cost to certify the Student = | L52: =D54 -> 0.028661759
...

Sheet Specialty (6)
A2: Certification Level: | C2: ='Total Course Profit'!B23
A5: E | B5: Approximate program size & average
A7: Is this a new program?(Yes or No) | G7: no | K7: Total Students per year: | L7: ='Data Entry'!G21 -> 371
A8: Students per year this level: | G8: 1
A9: Average Class size: | G9: 1
A11: F | B11: Determine short-term expenses per student in class
A13: Expenses | G13: Cost
A14: PADI Student Diver Materials | G14: 0 | I14: Cost per student in class | L14: =G14 -> 0
A15: Certificate/Diploma | G15: 0 | I15: Cost per student in class | L15: =G15 -> 0
A16: Emblem | G16: 0 | I16: Cost per student in class | L16: =G16 -> 0
A17: PIC | G17: 0 | I17: Cost per student in class | L17: =G17 -> 0
A18: Incidentals (Folders, Form, etc) | G18: 0 | I18: Cost per student in class | L18: =G18 -> 0
A19: Boat Fees | G19: 0 | I19: Cost per student in class | L19: =G19 -> 0
A20: Dive Site Entrance Fees | G20: 0 | I20: Cost per student in class | L20: =G20 -> 0
A21: Other | G21: 0 | I21: Cost per student in class | L21: =G21 -> 0
A22: Other | G22: 0 | I22: Cost per student in class | L22: =G22 -> 0
A23: Other | G23: 0 | I23: Cost per student in class | L23: =G23 -> 0
K24: Total | L24: =SUM(L14:L23) -> 0
A26: Expenses | G26: Cost
A27: Fee for classroom facilities | G27: 0 | I27: Cost divided by # of students in class | L27: =G27/$G$9 -> 0
A28: Fee for pool facilities | G28: 0 | I28: Cost divided by # of students in class | L28: =G28/$G$9 -> 0
A29: Air fills for pool and Open Water | E29: #fills per diver
E30: 0 | G30: 0 | I30: Cost X # of required refills | L30: =SUM(E30*G30) -> 0
A31: Instructor wages per participant | D31: Class&Pool | E31: TD's
B32: (enter pay) | D32: 0 | E32: 0 | G32: =SUM(D32+E32)*G9 -> 0 | I32: Cost divided by # of students in class | L32: =SUM(G32/G9) -> 0
A33: Assistants wages per Course | G33: 0 | I33: Cost divided by # of students in class | L33: =G33/$G$9 -> 0
A34: Dive Ctr. vehicle; depreciation after one year | G34: 0 | I34: Cost divided by # of students in class | L34: =G34/$G$9 -> 0
A35: Vehicle insurance | G35: 0 | I35: Cost divided by # of students in class | L35: =G35/$G$9 -> 0
A36: Fuel used for course work | G36: 0 | I36: Cost divided by # of students in class | L36: =G36/$G$9 -> 0
A37: Course Specific equipment | E37: Life (years)
E38: 1 | G38: 0 | I38: Cost divided by # of students in class | L38: =SUM(G38/E38)/G9 -> 0
A39: Other | G39: 0 | I39: Cost divided by # of students in class | L39: =G39/$G$9 -> 0
A40: Other | G40: 0 | I40: Cost divided by # of students in class | L40: =G40/$G$9 -> 0
A41: Other | G41: 0 | I41: Cost divided by # of students in class | L41: =G41/$G$9 -> 0
I42: Total | L42: =SUM(L27:L41) -> 0
J44: Total Variable Expenses= | L44: =L24+L42 -> 0
A47: G | B47: Desired Profit Margin | G47: 0.25
A49: H | B49: Determine total cost of course per student
K50: Fixed Expenses | L50: =' Fixed Expenses'!L66 -> 10.633512
C52: Total Fixed Expenses = | D52: =SUM(L50*H53) -> 0.028661759 | K52: Cost to certify the Student = | L52: =D54 -> 0.028661759
...

Sheet Specialty (7)
A2: Certification Level: | C2: ='Total Course Profit'!B24 -> 0
A5: E | B5: Approximate program size & average
A7: Is this a new program?(Yes or No) | G7: no | K7: Total Students per year: | L7: ='Data Entry'!G21 -> 371
A8: Students per year this level: | G8: 1
A9: Average Class size: | G9: 1
A11: F | B11: Determine short-term expenses per student in class
A13: Expenses | G13: Cost
A14: PADI Student Diver Materials | G14: 0 | I14: Cost per student in class | L14: =G14 -> 0
A15: Certificate/Diploma | G15: 0 | I15: Cost per student in class | L15: =G15 -> 0
A16: Emblem | G16: 0 | I16: Cost per student in class | L16: =G16 -> 0
A17: PIC | G17: 0 | I17: Cost per student in class | L17: =G17 -> 0
A18: Incidentals (Folders, Form, etc) | G18: 0 | I18: Cost per student in class | L18: =G18 -> 0
A19: Boat Fees | G19: 0 | I19: Cost per student in class | L19: =G19 -> 0
A20: Dive Site Entrance Fees | G20: 0 | I20: Cost per student in class | L20: =G20 -> 0
A21: Other | G21: 0 | I21: Cost per student in class | L21: =G21 -> 0
A22: Other | G22: 0 | I22: Cost per student in class | L22: =G22 -> 0
A23: Other | G23: 0 | I23: Cost per student in class | L23: =G23 -> 0
K24: Total | L24: =SUM(L14:L23) -> 0
A26: Expenses | G26: Cost
A27: Fee for classroom facilities | G27: 0 | I27: Cost divided by # of students in class | L27: =G27/$G$9 -> 0
A28: Fee for pool facilities | G28: 0 | I28: Cost divided by # of students in class | L28: =G28/$G$9 -> 0
A29: Air fills for pool and Open Water | E29: #fills per diver
E30: 0 | G30: 0 | I30: Cost X # of required refills | L30: =SUM(E30*G30) -> 0
